Workbook
Name Slicer_AGE_GROUP: #N/A
Name Slicer_Education: #N/A
Name Slicer_Income: #N/A
Name Slicer_Kidhome: #N/A
Name Slicer_Marital_Status: #N/A
Name Slicer_TOTAL_PURCHASE: #N/A
Name Slicer_Year_Birth: #N/A

Sheet customer_dataset
A1: Dataset - 1 | K1: Dataset - 2 | O1: 1.(Step) : Answers | R1: 2.(Step) : Answers | U1: 3.(Step) : Answers
A2: Column1 | B2: ID | C2: Year_Birth | D2: Education | E2: Marital_Status | F2: Income | G2: Kidhome | H2: Teenhome | I2: Dt_Customer | J2: Recency | K2: MntFruits | L2: MntSweetProducts | M2: NumWebPurchases | N2: NumStorePurchases | O2: AGE | P2: AGE GROUP | Q2: TOTAL PURCHASE | R2: Product Category | S2: Total Sales Amount | U2: Income group | W2: Lifespan years
A3: 0 | B3: 5524 | C3: 1957 | D3: Graduation | E3: Single | F3: 58138 | G3: 0 | H3: 0 | I3: 41156 | J3: 58 | K3: =VLOOKUP(B3,purchase_dataset!$B$2:$F$2241,2,FALSE) -> 88 | L3: =VLOOKUP(B3,purchase_dataset!$B$2:$F$2241,3,FALSE) -> 88 | M3: =VLOOKUP(B3,purchase_dataset!$B$2:$F$2241,3,FALSE) -> 88 | N3: =VLOOKUP(B3,purchase_dataset!$B$2:$F$2241,5,FALSE) -> 4 | O3: {=2026-C3:C2242} -> 69 | P3: =IF(O3<30,"30",IF(O3<=50,"30-50",">50")) -> >50 | Q3: =M3+N3 -> 92 | R3: Sweet products | S3: =SUM(L3:L2242) -> 60621 | U3: {=_xlfn.IFS(F3<30000,"30k",F3<=50000,"30k-50k",F3<=75000,"50k-75k",F3<=100000,"75k-100k",F3>100000,"100k")} -> 50k-75k | W3: =2026-YEAR(I3) -> 14
A4: 1 | B4: 2174 | C4: 1954 | D4: Graduation | E4: Single | F4: 46344 | G4: 1 | H4: 1 | I4: 41706 | J4: 38 | K4: =VLOOKUP(B4,purchase_dataset!$B$2:$F$2241,2,FALSE) -> 1 | L4: =VLOOKUP(B4,purchase_dataset!$B$2:$F$2241,3,FALSE) -> 1 | M4: =VLOOKUP(B4,purchase_dataset!$B$2:$F$2241,3,FALSE) -> 1 | N4: =VLOOKUP(B4,purchase_dataset!$B$2:$F$2241,5,FALSE) -> 2 | O4: 72 | P4: =IF(O4<30,"30",IF(O4<=50,"30-50",">50")) -> >50 | Q4: =M4+N4 -> 3 | R4: Fruits | S4: =SUM(K3:K2242) -> 58917 | U4: {=_xlfn.IFS(F4<30000,"30k",F4<=50000,"30k-50k",F4<=75000,"50k-75k",F4<=100000,"75k-100k",F4>100000,"100k")} -> 30k-50k | W4: =2026-YEAR(I4) -> 12
A5: 2 | B5: 4141 | C5: 1965 | D5: Graduation | E5: Together | F5: 71613 | G5: 0 | H5: 0 | I5: 41507 | J5: 26 | K5: =VLOOKUP(B5,purchase_dataset!$B$2:$F$2241,2,FALSE) -> 49 | L5: =VLOOKUP(B5,purchase_dataset!$B$2:$F$2241,3,FALSE) -> 21 | M5: =VLOOKUP(B5,purchase_dataset!$B$2:$F$2241,3,FALSE) -> 21 | N5: =VLOOKUP(B5,purchase_dataset!$B$2:$F$2241,5,FALSE) -> 10 | O5: 61 | P5: =IF(O5<30,"30",IF(O5<=50,"30-50",">50")) -> >50 | Q5: =M5+N5 -> 31 | R5: Total Combined | S5: =S3+S4 -> 119538 | U5: {=_xlfn.IFS(F5<30000,"30k",F5<=50000,"30k-50k",F5<=75000,"50k-75k",F5<=100000,"75k-100k",F5>100000,"100k")} -> 50k-75k | W5: =2026-YEAR(I5) -> 13
A6: 3 | B6: 6182 | C6: 1984 | D6: Graduation | E6: Together | F6: 26646 | G6: 1 | H6: 0 | I6: 41680 | J6: 26 | K6: =VLOOKUP(B6,purchase_dataset!$B$2:$F$2241,2,FALSE) -> 4 | L6: =VLOOKUP(B6,purchase_dataset!$B$2:$F$2241,3,FALSE) -> 3 | M6: =VLOOKUP(B6,purchase_dataset!$B$2:$F$2241,3,FALSE) -> 3 | N6: =VLOOKUP(B6,purchase_dataset!$B$2:$F$2241,5,FALSE) -> 4 | O6: 42 | P6: =IF(O6<30,"30",IF(O6<=50,"30-50",">50")) -> 30-50 | Q6: =M6+N6 -> 7 | U6: {=_xlfn.IFS(F6<30000,"30k",F6<=50000,"30k-50k",F6<=75000,"50k-75k",F6<=100000,"75k-100k",F6>100000,"100k")} -> 30k | W6: =2026-YEAR(I6) -> 12
A7: 4 | B7: 5324 | C7: 1981 | D7: PhD | E7: Married | F7: 58293 | G7: 1 | H7: 0 | I7: 41658 | J7: 94 | K7: =VLOOKUP(B7,purchase_dataset!$B$2:$F$2241,2,FALSE) -> 43 | L7: =VLOOKUP(B7,purchase_dataset!$B$2:$F$2241,3,FALSE) -> 27 | M7: =VLOOKUP(B7,purchase_dataset!$B$2:$F$2241,3,FALSE) -> 27 | N7: =VLOOKUP(B7,purchase_dataset!$B$2:$F$2241,5,FALSE) -> 6 | O7: 45 | P7: =IF(O7<30,"30",IF(O7<=50,"30-50",">50")) -> 30-50 | Q7: =M7+N7 -> 33 | U7: {=_xlfn.IFS(F7<30000,"30k",F7<=50000,"30k-50k",F7<=75000,"50k-75k",F7<=100000,"75k-100k",F7>100000,"100k")} -> 50k-75k | W7: =2026-YEAR(I7) -> 12
A8: 5 | B8: 7446 | C8: 1967 | D8: Master | E8: Together | F8: 62513 | G8: 0 | H8: 1 | I8: 41526 | J8: 16 | K8: =VLOOKUP(B8,purchase_dataset!$B$2:$F$2241,2,FALSE) -> 42 | L8: =VLOOKUP(B8,purchase_dataset!$B$2:$F$2241,3,FALSE) -> 42 | M8: =VLOOKUP(B8,purchase_dataset!$B$2:$F$2241,3,FALSE) -> 42 | N8: =VLOOKUP(B8,purchase_dataset!$B$2:$F$2241,5,FALSE) -> 10 | O8: 59 | P8: =IF(O8<30,"30",IF(O8<=50,"30-50",">50")) -> >50 | Q8: =M8+N8 -> 52 | U8: {=_xlfn.IFS(F8<30000,"30k",F8<=50000,"30k-50k",F8<=75000,"50k-75k",F8<=100000,"75k-100k",F8>100000,"100k")} -> 50k-75k | W8: =2026-YEAR(I8) -> 13
A9: 6 | B9: 965 | C9: 1971 | D9: Graduation | E9: Divorced | F9: 55635 | G9: 0 | H9: 1 | I9: 41226 | J9: 34 | K9: =VLOOKUP(B9,purchase_dataset!$B$2:$F$2241,2,FALSE) -> 65 | L9: =VLOOKUP(B9,purchase_dataset!$B$2:$F$2241,3,FALSE) -> 49 | M9: =VLOOKUP(B9,purchase_dataset!$B$2:$F$2241,3,FALSE) -> 49 | N9: =VLOOKUP(B9,purchase_dataset!$B$2:$F$2241,5,FALSE) -> 7 | O9: 55 | P9: =IF(O9<30,"30",IF(O9<=50,"30-50",">50")) -> >50 | Q9: =M9+N9 -> 56 | U9: {=_xlfn.IFS(F9<30000,"30k",F9<=50000,"30k-50k",F9<=75000,"50k-75k",F9<=100000,"75k-100k",F9>100000,"100k")} -> 50k-75k | W9: =2026-YEAR(I9) -> 14
A10: 7 | B10: 6177 | C10: 1985 | D10: PhD | E10: Married | F10: 33454 | G10: 1 | H10: 0 | I10: 41402 | J10: 32 | K10: =VLOOKUP(B10,purchase_dataset!$B$2:$F$2241,2,FALSE) -> 10 | L10: =VLOOKUP(B10,purchase_dataset!$B$2:$F$2241,3,FALSE) -> 1 | M10: =VLOOKUP(B10,purchase_dataset!$B$2:$F$2241,3,FALSE) -> 1 | N10: =VLOOKUP(B10,purchase_dataset!$B$2:$F$2241,5,FALSE) -> 4 | O10: 41 | P10: =IF(O10<30,"30",IF(O10<=50,"30-50",">50")) -> 30-50 | Q10: =M10+N10 -> 5 | U10: {=_xlfn.IFS(F10<30000,"30k",F10<=50000,"30k-50k",F10<=75000,"50k-75k",F10<=100000,"75k-100k",F10>100000,"100k")} -> 30k-50k | W10: =2026-YEAR(I10) -> 13
A11: 8 | B11: 4855 | C11: 1974 | D11: PhD | E11: Together | F11: 30351 | G11: 1 | H11: 0 | I11: 41431 | J11: 19 | K11: =VLOOKUP(B11,purchase_dataset!$B$2:$F$2241,2,FALSE) -> 0 | L11: =VLOOKUP(B11,purchase_dataset!$B$2:$F$2241,3,FALSE) -> 3 | M11: =VLOOKUP(B11,purchase_dataset!$B$2:$F$2241,3,FALSE) -> 3 | N11: =VLOOKUP(B11,purchase_dataset!$B$2:$F$2241,5,FALSE) -> 2 | O11: 52 | P11: =IF(O11<30,"30",IF(O11<=50,"30-50",">50")) -> >50 | Q11: =M11+N11 -> 5 | U11: {=_xlfn.IFS(F11<30000,"30k",F11<=50000,"30k-50k",F11<=75000,"50k-75k",F11<=100000,"75k-100k",F11>100000,"100k")} -> 30k-50k | W11: =2026-YEAR(I11) -> 13
A12: 9 | B12: 5899 | C12: 1950 | D12: PhD | E12: Together | F12: 5648 | G12: 1 | H12: 1 | I12: 41711 | J12: 68 | K12: =VLOOKUP(B12,purchase_dataset!$B$2:$F$2241,2,FALSE) -> 0 | L12: =VLOOKUP(B12,purchase_dataset!$B$2:$F$2241,3,FALSE) -> 1 | M12: =VLOOKUP(B12,purchase_dataset!$B$2:$F$2241,3,FALSE) -> 1 | N12: =VLOOKUP(B12,purchase_dataset!$B$2:$F$2241,5,FALSE) -> 0 | O12: 76 | P12: =IF(O12<30,"30",IF(O12<=50,"30-50",">50")) -> >50 | Q12: =M12+N12 -> 1 | U12: {=_xlfn.IFS(F12<30000,"30k",F12<=50000,"30k-50k",F12<=75000,"50k-75k",F12<=100000,"75k-100k",F12>100000,"100k")} -> 30k | W12: =2026-YEAR(I12) -> 12
A13: 10 | B13: 1994 | C13: 1983 | D13: Graduation | E13: Married | G13: 1 | H13: 0 | I13: 41593 | J13: 11 | K13: =VLOOKUP(B13,purchase_dataset!$B$2:$F$2241,2,FALSE) -> 5 | L13: =VLOOKUP(B13,purchase_dataset!$B$2:$F$2241,3,FALSE) -> 2 | M13: =VLOOKUP(B13,purchase_dataset!$B$2:$F$2241,3,FALSE) -> 2 | N13: =VLOOKUP(B13,purchase_dataset!$B$2:$F$2241,5,FALSE) -> 2 | O13: 43 | P13: =IF(O13<30,"30",IF(O13<=50,"30-50",">50")) -> 30-50 | Q13: =M13+N13 -> 4 | U13: {=_xlfn.IFS(F13<30000,"30k",F13<=50000,"30k-50k",F13<=75000,"50k-75k",F13<=100000,"75k-100k",F13>100000,"100k")} -> 30k | W13: =2026-YEAR(I13) -> 13
A14: 11 | B14: 387 | C14: 1976 | D14: Basic | E14: Married | F14: 7500 | G14: 0 | H14: 0 | I14: 41226 | J14: 59 | K14: =VLOOKUP(B14,purchase_dataset!$B$2:$F$2241,2,FALSE) -> 16 | L14: =VLOOKUP(B14,purchase_dataset!$B$2:$F$2241,3,FALSE) -> 1 | M14: =VLOOKUP(B14,purchase_dataset!$B$2:$F$2241,3,FALSE) -> 1 | N14: =VLOOKUP(B14,purchase_dataset!$B$2:$F$2241,5,FALSE) -> 3 | O14: 50 | P14: =IF(O14<30,"30",IF(O14<=50,"30-50",">50")) -> 30-50 | Q14: =M14+N14 -> 4 | U14: {=_xlfn.IFS(F14<30000,"30k",F14<=50000,"30k-50k",F14<=75000,"50k-75k",F14<=100000,"75k-100k",F14>100000,"100k")} -> 30k | W14: =2026-YEAR(I14) -> 14
A15: 12 | B15: 2125 | C15: 1959 | D15: Graduation | E15: Divorced | F15: 63033 | G15: 0 | H15: 0 | I15: 41593 | J15: 82 | K15: =VLOOKUP(B15,purchase_dataset!$B$2:$F$2241,2,FALSE) -> 61 | L15: =VLOOKUP(B15,purchase_dataset!$B$2:$F$2241,3,FALSE) -> 112 | M15: =VLOOKUP(B15,purchase_dataset!$B$2:$F$2241,3,FALSE) -> 112 | N15: =VLOOKUP(B15,purchase_dataset!$B$2:$F$2241,5,FALSE) -> 8 | O15: 67 | P15: =IF(O15<30,"30",IF(O15<=50,"30-50",">50")) -> >50 | Q15: =M15+N15 -> 120 | U15: {=_xlfn.IFS(F15<30000,"30k",F15<=50000,"30k-50k",F15<=75000,"50k-75k",F15<=100000,"75k-100k",F15>100000,"100k")} -> 50k-75k | W15: =2026-YEAR(I15) -> 13
A16: 13 | B16: 8180 | C16: 1952 | D16: Master | E16: Divorced | F16: 59354 | G16: 1 | H16: 1 | I16: 41593 | J16: 53 | K16: =VLOOKUP(B16,purchase_dataset!$B$2:$F$2241,2,FALSE) -> 2 | L16: =VLOOKUP(B16,purchase_dataset!$B$2:$F$2241,3,FALSE) -> 5 | M16: =VLOOKUP(B16,purchase_dataset!$B$2:$F$2241,3,FALSE) -> 5 | N16: =VLOOKUP(B16,purchase_dataset!$B$2:$F$2241,5,FALSE) -> 5 | O16: 74 | P16: =IF(O16<30,"30",IF(O16<=50,"30-50",">50")) -> >50 | Q16: =M16+N16 -> 10 | U16: {=_xlfn.IFS(F16<30000,"30k",F16<=50000,"30k-50k",F16<=75000,"50k-75k",F16<=100000,"75k-100k",F16>100000,"100k")} -> 50k-75k | W16: =2026-YEAR(I16) -> 13
A17: 14 | B17: 2569 | C17: 1987 | D17: Graduation | E17: Married | F17: 17323 | G17: 0 | H17: 0 | I17: 41192 | J17: 38 | K17: =VLOOKUP(B17,purchase_dataset!$B$2:$F$2241,2,FALSE) -> 14 | L17: =VLOOKUP(B17,purchase_dataset!$B$2:$F$2241,3,FALSE) -> 1 | M17: =VLOOKUP(B17,purchase_dataset!$B$2:$F$2241,3,FALSE) -> 1 | N17: =VLOOKUP(B17,purchase_dataset!$B$2:$F$2241,5,FALSE) -> 3 | O17: 39 | P17: =IF(O17<30,"30",IF(O17<=50,"30-50",">50")) -> 30-50 | Q17: =M17+N17 -> 4 | U17: {=_xlfn.IFS(F17<30000,"30k",F17<=50000,"30k-50k",F17<=75000,"50k-75k",F17<=100000,"75k-100k",F17>100000,"100k")} -> 30k | W17: =2026-YEAR(I17) -> 14
A18: 15 | B18: 2114 | C18: 1946 | D18: PhD | E18: Single | F18: 82800 | G18: 0 | H18: 0 | I18: 41237 | J18: 23 | K18: =VLOOKUP(B18,purchase_dataset!$B$2:$F$2241,2,FALSE) -> 22 | L18: =VLOOKUP(B18,purchase_dataset!$B$2:$F$2241,3,FALSE) -> 68 | M18: =VLOOKUP(B18,purchase_dataset!$B$2:$F$2241,3,FALSE) -> 68 | N18: =VLOOKUP(B18,purchase_dataset!$B$2:$F$2241,5,FALSE) -> 12 | O18: 80 | P18: =IF(O18<30,"30",IF(O18<=50,"30-50",">50")) -> >50 | Q18: =M18+N18 -> 80 | U18: {=_xlfn.IFS(F18<30000,"30k",F18<=50000,"30k-50k",F18<=75000,"50k-75k",F18<=100000,"75k-100k",F18>100000,"100k")} -> 75k-100k | W18: =2026-YEAR(I18) -> 14
A19: 16 | B19: 9736 | C19: 1980 | D19: Graduation | E19: Married | F19: 41850 | G19: 1 | H19: 1 | I19: 41267 | J19: 51 | K19: =VLOOKUP(B19,purchase_dataset!$B$2:$F$2241,2,FALSE) -> 5 | L19: =VLOOKUP(B19,purchase_dataset!$B$2:$F$2241,3,FALSE) -> 13 | M19: =VLOOKUP(B19,purchase_dataset!$B$2:$F$2241,3,FALSE) -> 13 | N19: =VLOOKUP(B19,purchase_dataset!$B$2:$F$2241,5,FALSE) -> 3 | O19: 46 | P19: =IF(O19<30,"30",IF(O19<=50,"30-50",">50")) -> 30-50 | Q19: =M19+N19 -> 16 | U19: {=_xlfn.IFS(F19<30000,"30k",F19<=50000,"30k-50k",F19<=75000,"50k-75k",F19<=100000,"75k-100k",F19>100000,"100k")} -> 30k-50k | W19: =2026-YEAR(I19) -> 14
A20: 17 | B20: 4939 | C20: 1946 | D20: Graduation | E20: Together | F20: 37760 | G20: 0 | H20: 0 | I20: 41152 | J20: 20 | K20: =VLOOKUP(B20,purchase_dataset!$B$2:$F$2241,2,FALSE) -> 5 | L20: =VLOOKUP(B20,purchase_dataset!$B$2:$F$2241,3,FALSE) -> 12 | M20: =VLOOKUP(B20,purchase_dataset!$B$2:$F$2241,3,FALSE) -> 12 | N20: =VLOOKUP(B20,purchase_dataset!$B$2:$F$2241,5,FALSE) -> 6 | O20: 80 | P20: =IF(O20<30,"30",IF(O20<=50,"30-50",">50")) -> >50 | Q20: =M20+N20 -> 18 | U20: {=_xlfn.IFS(F20<30000,"30k",F20<=50000,"30k-50k",F20<=75000,"50k-75k",F20<=100000,"75k-100k",F20>100000,"100k")} -> 30k-50k | W20: =2026-YEAR(I20) -> 14
A21: 18 | B21: 6565 | C21: 1949 | D21: Master | E21: Married | F21: 76995 | G21: 0 | H21: 1 | I21: 41361 | J21: 91 | K21: =VLOOKUP(B21,purchase_dataset!$B$2:$F$2241,2,FALSE) -> 80 | L21: =VLOOKUP(B21,purchase_dataset!$B$2:$F$2241,3,FALSE) -> 16 | M21: =VLOOKUP(B21,purchase_dataset!$B$2:$F$2241,3,FALSE) -> 16 | N21: =VLOOKUP(B21,purchase_dataset!$B$2:$F$2241,5,FALSE) -> 9 | O21: 77 | P21: =IF(O21<30,"30",IF(O21<=50,"30-50",">50")) -> >50 | Q21: =M21+N21 -> 25 | U21: {=_xlfn.IFS(F21<30000,"30k",F21<=50000,"30k-50k",F21<=75000,"50k-75k",F21<=100000,"75k-100k",F21>100000,"100k")} -> 75k-100k | W21: =2026-YEAR(I21) -> 13
A22: 19 | B22: 2278 | C22: 1985 | D22: 2n Cycle | E22: Single | F22: 33812 | G22: 1 | H22: 0 | I22: 41216 | J22: 86 | K22: =VLOOKUP(B22,purchase_dataset!$B$2:$F$2241,2,FALSE) -> 17 | L22: =VLOOKUP(B22,purchase_dataset!$B$2:$F$2241,3,FALSE) -> 24 | M22: =VLOOKUP(B22,purchase_dataset!$B$2:$F$2241,3,FALSE) -> 24 | N22: =VLOOKUP(B22,purchase_dataset!$B$2:$F$2241,5,FALSE) -> 3 | O22: 41 | P22: =IF(O22<30,"30",IF(O22<=50,"30-50",">50")) -> 30-50 | Q22: =M22+N22 -> 27 | U22: {=_xlfn.IFS(F22<30000,"30k",F22<=50000,"30k-50k",F22<=75000,"50k-75k",F22<=100000,"75k-100k",F22>100000,"100k")} -> 30k-50k | W22: =2026-YEAR(I22) -> 14
A23: 20 | B23: 9360 | C23: 1982 | D23: Graduation | E23: Married | F23: 37040 | G23: 0 | H23: 0 | I23: 41129 | J23: 41 | K23: =VLOOKUP(B23,purchase_dataset!$B$2:$F$2241,2,FALSE) -> 2 | L23: =VLOOKUP(B23,purchase_dataset!$B$2:$F$2241,3,FALSE) -> 38 | M23: =VLOOKUP(B23,purchase_dataset!$B$2:$F$2241,3,FALSE) -> 38 | N23: =VLOOKUP(B23,purchase_dataset!$B$2:$F$2241,5,FALSE) -> 5 | O23: 44 | P23: =IF(O23<30,"30",IF(O23<=50,"30-50",">50")) -> 30-50 | Q23: =M23+N23 -> 43 | U23: {=_xlfn.IFS(F23<30000,"30k",F23<=50000,"30k-50k",F23<=75000,"50k-75k",F23<=100000,"75k-100k",F23>100000,"100k")} -> 30k-50k | W23: =2026-YEAR(I23) -> 14
A24: 21 | B24: 5376 | C24: 1979 | D24: Graduation | E24: Married | F24: 2447 | G24: 1 | H24: 0 | I24: 41280 | J24: 42 | K24: =VLOOKUP(B24,purchase_dataset!$B$2:$F$2241,2,FALSE) -> 1 | L24: =VLOOKUP(B24,purchase_dataset!$B$2:$F$2241,3,FALSE) -> 1 | M24: =VLOOKUP(B24,purchase_dataset!$B$2:$F$2241,3,FALSE) -> 1 | N24: =VLOOKUP(B24,purchase_dataset!$B$2:$F$2241,5,FALSE) -> 0 | O24: 47 | P24: =IF(O24<30,"30",IF(O24<=50,"30-50",">50")) -> 30-50 | Q24: =M24+N24 -> 1 | U24: {=_xlfn.IFS(F24<30000,"30k",F24<=50000,"30k-50k",F24<=75000,"50k-75k",F24<=100000,"75k-100k",F24>100000,"100k")} -> 30k | W24: =2026-YEAR(I24) -> 13
A25: 22 | B25: 1993 | C25: 1949 | D25: PhD | E25: Married | F25: 58607 | G25: 0 | H25: 1 | I25: 41266 | J25: 63 | K25: =VLOOKUP(B25,purchase_dataset!$B$2:$F$2241,2,FALSE) -> 0 | L25: =VLOOKUP(B25,purchase_dataset!$B$2:$F$2241,3,FALSE) -> 0 | M25: =VLOOKUP(B25,purchase_dataset!$B$2:$F$2241,3,FALSE) -> 0 | N25: =VLOOKUP(B25,purchase_dataset!$B$2:$F$2241,5,FALSE) -> 9 | O25: 77 | P25: =IF(O25<30,"30",IF(O25<=50,"30-50",">50")) -> >50 | Q25: =M25+N25 -> 9 | U25: {=_xlfn.IFS(F25<30000,"30k",F25<=50000,"30k-50k",F25<=75000,"50k-75k",F25<=100000,"75k-100k",F25>100000,"100k")} -> 50k-75k | W25: =2026-YEAR(I25) -> 14
... A29: 26 | B29: 2404 | C29: 1976 | D29: Graduation | E29: Married | F29: 53359 | G29: 1 | H29: 1 | I29: 41421 | J29: 4 | K29: =VLOOKUP(B29,purchase_dataset!$B$2:$F$2241,2,FALSE) -> 4 | L29: =VLOOKUP(B29,purchase_dataset!$B$2:$F$2241,3,FALSE) -> 6 | M29: =VLOOKUP(B29,purchase_dataset!$B$2:$F$2241,3,FALSE) -> 6 | N29: =VLOOKUP(B29,purchase_dataset!$B$2:$F$2241,5,FALSE) -> 4 | O29: 50 | P29: =IF(O29<30,"30",IF(O29<=50,"30-50",">50")) -> 30-50 | Q29: =M29+N29 -> 10 | U29: {=_xlfn.IFS(F29<30000,"30k",F29<=50000,"30k-50k",F29<=75000,"50k-75k",F29<=100000,"75k-100k",F29>100000,"100k")} -> 50k-75k | W29: =2026-YEAR(I29) -> 13
A30: 27 | B30: 5255 | C30: 1986 | D30: Graduation | E30: Single | G30: 1 | H30: 0 | I30: 41325 | J30: 19 | K30: =VLOOKUP(B30,purchase_dataset!$B$2:$F$2241,2,FALSE) -> 1 | L30: =VLOOKUP(B30,purchase_dataset!$B$2:$F$2241,3,FALSE) -> 263 | M30: =VLOOKUP(B30,purchase_dataset!$B$2:$F$2241,3,FALSE) -> 263 | N30: =VLOOKUP(B30,purchase_dataset!$B$2:$F$2241,5,FALSE) -> 0 | O30: 40 | P30: =IF(O30<30,"30",IF(O30<=50,"30-50",">50")) -> 30-50 | Q30: =M30+N30 -> 263 | U30: {=_xlfn.IFS(F30<30000,"30k",F30<=50000,"30k-50k",F30<=75000,"50k-75k",F30<=100000,"75k-100k",F30>100000,"100k")} -> 30k | W30: =2026-YEAR(I30) -> 13
A31: 28 | B31: 9422 | C31: 1989 | D31: Graduation | E31: Married | F31: 38360 | G31: 1 | H31: 0 | I31: 41425 | J31: 26 | K31: =VLOOKUP(B31,purchase_dataset!$B$2:$F$2241,2,FALSE) -> 2 | L31: =VLOOKUP(B31,purchase_dataset!$B$2:$F$2241,3,FALSE) -> 21 | M31: =VLOOKUP(B31,purchase_dataset!$B$2:$F$2241,3,FALSE) -> 21 | N31: =VLOOKUP(B31,purchase_dataset!$B$2:$F$2241,5,FALSE) -> 4 | O31: 37 | P31: =IF(O31<30,"30",IF(O31<=50,"30-50",">50")) -> 30-50 | Q31: =M31+N31 -> 25 | U31: {=_xlfn.IFS(F31<30000,"30k",F31<=50000,"30k-50k",F31<=75000,"50k-75k",F31<=100000,"75k-100k",F31>100000,"100k")} -> 30k-50k | W31: =2026-YEAR(I31) -> 13
A32: 29 | B32: 1966 | C32: 1965 | D32: PhD | E32: Married | F32: 84618 | G32: 0 | H32: 0 | I32: 41600 | J32: 96 | K32: =VLOOKUP(B32,purchase_dataset!$B$2:$F$2241,2,FALSE) -> 100 | L32: =VLOOKUP(B32,purchase_dataset!$B$2:$F$2241,3,FALSE) -> 66 | M32: =VLOOKUP(B32,purchase_dataset!$B$2:$F$2241,3,FALSE) -> 66 | N32: =VLOOKUP(B32,purchase_dataset!$B$2:$F$2241,5,FALSE) -> 10 | O32: 61 | P32: =IF(O32<30,"30",IF(O32<=50,"30-50",">50")) -> >50 | Q32: =M32+N32 -> 76 | U32: {=_xlfn.IFS(F32<30000,"30k",F32<=50000,"30k-50k",F32<=75000,"50k-75k",F32<=100000,"75k-100k",F32>100000,"100k")} -> 75k-100k | W32: =2026-YEAR(I32) -> 13
A33: 30 | B33: 6864 | C33: 1989 | D33: Master | E33: Divorced | F33: 10979 | G33: 0 | H33: 0 | I33: 41781 | J33: 34 | K33: =VLOOKUP(B33,purchase_dataset!$B$2:$F$2241,2,FALSE) -> 4 | L33: =VLOOKUP(B33,purchase_dataset!$B$2:$F$2241,3,FALSE) -> 2 | M33: =VLOOKUP(B33,purchase_dataset!$B$2:$F$2241,3,FALSE) -> 2 | N33: =VLOOKUP(B33,purchase_dataset!$B$2:$F$2241,5,FALSE) -> 3 | O33: 37 | P33: =IF(O33<30,"30",IF(O33<=50,"30-50",">50")) -> 30-50 | Q33: =M33+N33 -> 5 | U33: {=_xlfn.IFS(F33<30000,"30k",F33<=50000,"30k-50k",F33<=75000,"50k-75k",F33<=100000,"75k-100k",F33>100000,"100k")} -> 30k | W33: =2026-YEAR(I33) -> 12
A34: 31 | B34: 3033 | C34: 1963 | D34: Master | E34: Together | F34: 38620 | G34: 0 | H34: 0 | I34: 41405 | J34: 56 | K34: =VLOOKUP(B34,purchase_dataset!$B$2:$F$2241,2,FALSE) -> 17 | L34: =VLOOKUP(B34,purchase_dataset!$B$2:$F$2241,3,FALSE) -> 22 | M34: =VLOOKUP(B34,purchase_dataset!$B$2:$F$2241,3,FALSE) -> 22 | N34: =VLOOKUP(B34,purchase_dataset!$B$2:$F$2241,5,FALSE) -> 3 | O34: 63 | P34: =IF(O34<30,"30",IF(O34<=50,"30-50",">50")) -> >50 | Q34: =M34+N34 -> 25 | U34: {=_xlfn.IFS(F34<30000,"30k",F34<=50000,"30k-50k",F34<=75000,"50k-75k",F34<=100000,"75k-100k",F34>100000,"100k")} -> 30k-50k | W34: =2026-YEAR(I34) -> 13
A35: 32 | B35: 5710 | C35: 1970 | D35: Graduation | E35: Together | F35: 40548 | G35: 0 | H35: 1 | I35: 41192 | J35: 31 | K35: =VLOOKUP(B35,purchase_dataset!$B$2:$F$2241,2,FALSE) -> 0 | L35: =VLOOKUP(B35,purchase_dataset!$B$2:$F$2241,3,FALSE) -> 0 | M35: =VLOOKUP(B35,purchase_dataset!$B$2:$F$2241,3,FALSE) -> 0 | N35: =VLOOKUP(B35,purchase_dataset!$B$2:$F$2241,5,FALSE) -> 4 | O35: 56 | P35: =IF(O35<30,"30",IF(O35<=50,"30-50",">50")) -> >50 | Q35: =M35+N35 -> 4 | U35: {=_xlfn.IFS(F35<30000,"30k",F35<=50000,"30k-50k",F35<=75000,"50k-75k",F35<=100000,"75k-100k",F35>100000,"100k")} -> 30k-50k | W35: =2026-YEAR(I35) -> 14
A36: 33 | B36: 7373 | C36: 1952 | D36: PhD | E36: Divorced | F36: 46610 | G36: 0 | H36: 2 | I36: 41211 | J36: 8 | K36: =VLOOKUP(B36,purchase_dataset!$B$2:$F$2241,2,FALSE) -> 12 | L36: =VLOOKUP(B36,purchase_dataset!$B$2:$F$2241,3,FALSE) -> 22 | M36: =VLOOKUP(B36,purchase_dataset!$B$2:$F$2241,3,FALSE) -> 22 | N36: =VLOOKUP(B36,purchase_dataset!$B$2:$F$2241,5,FALSE) -> 6 | O36: 74 | P36: =IF(O36<30,"30",IF(O36<=50,"30-50",">50")) -> >50 | Q36: =M36+N36 -> 28 | U36: {=_xlfn.IFS(F36<30000,"30k",F36<=50000,"30k-50k",F36<=75000,"50k-75k",F36<=100000,"75k-100k",F36>100000,"100k")} -> 30k-50k | W36: =2026-YEAR(I36) -> 14
A37: 34 | B37: 8755 | C37: 1946 | D37: Master | E37: Married | F37: 68657 | G37: 0 | H37: 0 | I37: 41325 | J37: 4 | K37: =VLOOKUP(B37,purchase_dataset!$B$2:$F$2241,2,FALSE) -> 34 | L37: =VLOOKUP(B37,purchase_dataset!$B$2:$F$2241,3,FALSE) -> 68 | M37: =VLOOKUP(B37,purchase_dataset!$B$2:$F$2241,3,FALSE) -> 68 | N37: =VLOOKUP(B37,purchase_dataset!$B$2:$F$2241,5,FALSE) -> 9 | O37: 80 | P37: =IF(O37<30,"30",IF(O37<=50,"30-50",">50")) -> >50 | Q37: =M37+N37 -> 77 | U37: {=_xlfn.IFS(F37<30000,"30k",F37<=50000,"30k-50k",F37<=75000,"50k-75k",F37<=100000,"75k-100k",F37>100000,"100k")} -> 50k-75k | W37: =2026-YEAR(I37) -> 13
A38: 35 | B38: 10738 | C38: 1951 | D38: Master | E38: Single | F38: 49389 | G38: 1 | H38: 1 | I38: 41515 | J38: 55 | K38: =VLOOKUP(B38,purchase_dataset!$B$2:$F$2241,2,FALSE) -> 0 | L38: =VLOOKUP(B38,purchase_dataset!$B$2:$F$2241,3,FALSE) -> 1 | M38: =VLOOKUP(B38,purchase_dataset!$B$2:$F$2241,3,FALSE) -> 1 | N38: =VLOOKUP(B38,purchase_dataset!$B$2:$F$2241,5,FALSE) -> 3 | O38: 75 | P38: =IF(O38<30,"30",IF(O38<=50,"30-50",">50")) -> >50 | Q38: =M38+N38 -> 4 | U38: {=_xlfn.IFS(F38<30000,"30k",F38<=50000,"30k-50k",F38<=75000,"50k-75k",F38<=100000,"75k-100k",F38>100000,"100k")} -> 30k-50k | W38: =2026-YEAR(I38) -> 13
A39: 36 | B39: 4339 | C39: 1970 | D39: PhD | E39: Married | F39: 67353 | G39: 0 | H39: 1 | I39: 41639 | J39: 37 | K39: =VLOOKUP(B39,purchase_dataset!$B$2:$F$2241,2,FALSE) -> 17 | L39: =VLOOKUP(B39,purchase_dataset!$B$2:$F$2241,3,FALSE) -> 8 | M39: =VLOOKUP(B39,purchase_dataset!$B$2:$F$2241,3,FALSE) -> 8 | N39: =VLOOKUP(B39,purchase_dataset!$B$2:$F$2241,5,FALSE) -> 12 | O39: 56 | P39: =IF(O39<30,"30",IF(O39<=50,"30-50",">50")) -> >50 | Q39: =M39+N39 -> 20 | U39: {=_xlfn.IFS(F39<30000,"30k",F39<=50000,"30k-50k",F39<=75000,"50k-75k",F39<=100000,"75k-100k",F39>100000,"100k")} -> 50k-75k | W39: =2026-YEAR(I39) -> 13
A40: 37 | B40: 10755 | C40: 1976 | D40: 2n Cycle | E40: Married | F40: 23718 | G40: 1 | H40: 0 | I40: 41519 | J40: 76 | K40: =VLOOKUP(B40,purchase_dataset!$B$2:$F$2241,2,FALSE) -> 3 | L40: =VLOOKUP(B40,purchase_dataset!$B$2:$F$2241,3,FALSE) -> 7 | M40: =VLOOKUP(B40,purchase_dataset!$B$2:$F$2241,3,FALSE) -> 7 | N40: =VLOOKUP(B40,purchase_dataset!$B$2:$F$2241,5,FALSE) -> 2 | O40: 50 | P40: =IF(O40<30,"30",IF(O40<=50,"30-50",">50")) -> 30-50 | Q40: =M40+N40 -> 9 | U40: {=_xlfn.IFS(F40<30000,"30k",F40<=50000,"30k-50k",F40<=75000,"50k-75k",F40<=100000,"75k-100k",F40>100000,"100k")} -> 30k | W40: =2026-YEAR(I40) -> 13
A41: 38 | B41: 8595 | C41: 1973 | D41: Graduation | E41: Widow | F41: 42429 | G41: 0 | H41: 1 | I41: 41681 | J41: 99 | K41: =VLOOKUP(B41,purchase_dataset!$B$2:$F$2241,2,FALSE) -> 0 | L41: =VLOOKUP(B41,purchase_dataset!$B$2:$F$2241,3,FALSE) -> 0 | M41: =VLOOKUP(B41,purchase_dataset!$B$2:$F$2241,3,FALSE) -> 0 | N41: =VLOOKUP(B41,purchase_dataset!$B$2:$F$2241,5,FALSE) -> 3 | O41: 53 | P41: =IF(O41<30,"30",IF(O41<=50,"30-50",">50")) -> >50 | Q41: =M41+N41 -> 3 | U41: {=_xlfn.IFS(F41<30000,"30k",F41<=50000,"30k-50k",F41<=75000,"50k-75k",F41<=100000,"75k-100k",F41>100000,"100k")} -> 30k-50k | W41: =2026-YEAR(I41) -> 12
A42: 39 | B42: 2968 | C42: 1943 | D42: PhD | E42: Divorced | F42: 48948 | G42: 0 | H42: 0 | I42: 41306 | J42: 53 | K42: =VLOOKUP(B42,purchase_dataset!$B$2:$F$2241,2,FALSE) -> 8 | L42: =VLOOKUP(B42,purchase_dataset!$B$2:$F$2241,3,FALSE) -> 49 | M42: =VLOOKUP(B42,purchase_dataset!$B$2:$F$2241,3,FALSE) -> 49 | N42: =VLOOKUP(B42,purchase_dataset!$B$2:$F$2241,5,FALSE) -> 5 | O42: 83 | P42: =IF(O42<30,"30",IF(O42<=50,"30-50",">50")) -> >50 | Q42: =M42+N42 -> 54 | U42: {=_xlfn.IFS(F42<30000,"30k",F42<=50000,"30k-50k",F42<=75000,"50k-75k",F42<=100000,"75k-100k",F42>100000,"100k")} -> 30k-50k | W42: =2026-YEAR(I42) -> 13
... A45: 42 | B45: 8430 | C45: 1957 | D45: Graduation | E45: Together | F45: 21994 | G45: 0 | H45: 1 | I45: 41267 | J45: 4 | K45: =VLOOKUP(B45,purchase_dataset!$B$2:$F$2241,2,FALSE) -> 0 | L45: =VLOOKUP(B45,purchase_dataset!$B$2:$F$2241,3,FALSE) -> 1 | M45: =VLOOKUP(B45,purchase_dataset!$B$2:$F$2241,3,FALSE) -> 1 | N45: =VLOOKUP(B45,purchase_dataset!$B$2:$F$2241,5,FALSE) -> 3 | O45: 69 | P45: =IF(O45<30,"30",IF(O45<=50,"30-50",">50")) -> >50 | Q45: =M45+N45 -> 4 | U45: {=_xlfn.IFS(F45<30000,"30k",F45<=50000,"30k-50k",F45<=75000,"50k-75k",F45<=100000,"75k-100k",F45>100000,"100k")} -> 30k | W45: =2026-YEAR(I45) -> 14
...

Sheet purchase_dataset
A1: Column1 | B1: ID | C1: MntFruits | D1: MntSweetProducts | E1: NumWebPurchases | F1: NumStorePurchases
A2: 1898 | B2: 4619 | C2: 2 | D2: 262 | E2: 27 | F2: 0
A3: 27 | B3: 5255 | C3: 1 | D3: 263 | E3: 27 | F3: 0
A4: 1975 | B4: 10311 | C4: 4 | D4: 4 | E4: 25 | F4: 0
A5: 1806 | B5: 6237 | C5: 4 | D5: 2 | E5: 23 | F5: 1
A6: 336 | B6: 7381 | C6: 153 | D6: 97 | E6: 11 | F6: 6
A7: 1924 | B7: 7966 | C7: 137 | D7: 22 | E7: 11 | F7: 11
A8: 681 | B8: 4910 | C8: 134 | D8: 134 | E8: 11 | F8: 13
A9: 2013 | B9: 1951 | C9: 122 | D9: 129 | E9: 11 | F9: 8
A10: 1507 | B10: 7706 | C10: 104 | D10: 151 | E10: 11 | F10: 5
A11: 924 | B11: 8931 | C11: 99 | D11: 149 | E11: 11 | F11: 10
A12: 767 | B12: 1911 | C12: 97 | D12: 133 | E12: 11 | F12: 12
A13: 1488 | B13: 9743 | C13: 89 | D13: 35 | E13: 11 | F13: 8
... A2241: 2019 | B2241: 2375 | C2241: 0 | D2241: 3 | E2241: 0 | F2241: 3

Sheet Pivot
A1: Row Labels | B1: Sum of TOTAL PURCHASE
A2: >50 | B2: 51375
A3: 30-50 | B3: 22216
A4: Grand Total | B4: 73591
A6: Row Labels | B6: Sum of Total Sales Amount
A7: Fruits | B7: 58917
A8: Sweet products | B8: 60621
A9: Total Combined | B9: 119538
A10: Grand Total | B10: 239076
A12: Row Labels | B12: Average of Lifespan years | C12: Sum of TOTAL PURCHASE | D12: Average of TOTAL PURCHASE | F12: Row Labels | G12: Average of Lifespan years | H12: Sum of TOTAL PURCHASE | I12: Average of TOTAL PURCHASE
A13: 30k | B13: 13.017766 | C13: 4181 | D13: 10.611675 | F13: =A13 -> 30k | G13: {=B13:B17} -> 13.017766 | H13: {=C13:C17} -> 4181 | I13: {=D13:D17} -> 10.611675
A14: 30k-50k | B14: 12.946377 | C14: 7806 | D14: 11.313043 | F14: =A14 -> 30k-50k | G14: 12.946377 | H14: 7806 | I14: 11.313043
A15: 50k-75k | B15: 13.003764 | C15: 34370 | D15: 43.124216 | F15: =A15 -> 50k-75k | G15: 13.003764 | H15: 34370 | I15: 43.124216
A16: 75k-100k | B16: 12.898844 | C16: 26466 | D16: 76.491329 | F16: =A16 -> 75k-100k | G16: 12.898844 | H16: 26466 | I16: 76.491329
A17: 100k | B17: 12.923077 | C17: 768 | D17: 59.076923 | F17: =A17 -> 100k | G17: 12.923077 | H17: 768 | I17: 59.076923
A18: Grand Total | B18: 12.971875 | C18: 73591 | D18: 32.853125
A21: Row Labels | B21: Sum of TOTAL PURCHASE | C21: Average of Income | D21: Average of TOTAL PURCHASE
A22: 2n Cycle | B22: 8071 | C22: 47633.19 | D22: 39.758621
A23: Basic | B23: 808 | C23: 20306.259 | D23: 14.962963
A24: Graduation | B24: 41921 | C24: 52720.374 | D24: 37.196983
A25: Master | B25: 10017 | C25: 52917.534 | D25: 27.072973
A26: PhD | B26: 12774 | C26: 56145.314 | D26: 26.283951
A27: Grand Total | B27: 73591 | C27: 52247.251 | D27: 32.853125
A30: Average of Recency | B30: Column Labels | L30: Average of Recency
A31: Row Labels | B31: Absurd | C31: Alone | D31: Divorced | E31: Married | F31: Single | G31: Together | H31: Widow | I31: YOLO | J31: Grand Total | L31: Row Labels | M31: Absurd | N31: Alone | O31: Divorced | P31: Married | Q31: Single | R31: Together | S31: Widow | T31: YOLO | U31: Grand Total
A32: 2n Cycle | D32: 45.26087 | E32: 48.444444 | F32: 44.081081 | G32: 51.45614 | H32: 60 | J32: 48.418719 | L32: 2n Cycle | O32: 45.26087 | P32: 48.444444 | Q32: 44.081081 | R32: 51.45614 | S32: 60 | U32: 48.418719
A33: Basic | D33: 31 | E33: 45.6 | F33: 50.166667 | G33: 49.5 | H33: 77 | J33: 48.444444 | L33: Basic | O33: 31 | P33: 45.6 | Q33: 50.166667 | R33: 49.5 | S33: 77 | U33: 48.444444
A34: Graduation | B34: 58 | C34: 12 | D34: 52.512605 | E34: 48.951501 | F34: 50.801587 | G34: 49.839161 | H34: 51.971429 | J34: 50.035492 | L34: Graduation | M34: 58 | N34: 12 | O34: 52.512605 | P34: 48.951501 | Q34: 50.801587 | R34: 49.839161 | S34: 51.971429 | U34: 50.035492
A35: Master | B35: 48 | C35: 42 | D35: 49.351351 | E35: 44.521739 | F35: 48.586667 | G35: 50.40566 | H35: 46.666667 | J35: 47.586486 | L35: Master | M35: 48 | N35: 42 | O35: 49.351351 | P35: 44.521739 | Q35: 48.586667 | R35: 50.40566 | S35: 46.666667 | U35: 47.586486
A36: PhD | C36: 37 | D36: 44.884615 | E36: 49.666667 | F36: 48.806122 | G36: 49.905983 | H36: 42.833333 | I36: 3 | J36: 48.483539 | L36: PhD | N36: 37 | O36: 44.884615 | P36: 49.666667 | Q36: 48.806122 | R36: 49.905983 | S36: 42.833333 | T36: 3 | U36: 48.483539
A37: Grand Total | B37: 53 | C37: 30.333333 | D37: 49.487069 | E37: 48.277778 | F37: 49.50625 | G37: 50.106897 | H37: 49.142857 | I37: 3 | J37: 49.109375 | L37: Grand Total | M37: 53 | N37: 30.333333 | O37: 49.487069 | P37: 48.277778 | Q37: 49.50625 | R37: 50.106897 | S37: 49.142857 | T37: 3 | U37: 49.109375
A42: Formulas | D42: Pivot Charts
A43: Total Revenue | D43: Age Group | E43: Sum of TOTAL PURCHASE
A44: 119538 | D44: >50 | E44: 51375
D45: 30-50 | E45: 22216
A46: Total Purchase Volume | D46: Grand Total | E46: 73591
A47: 73591
D48: Pivot Charts
A49: Total Average income | D49: Age Group | E49: Sum of Total Sales Amount
A50: 52247.251 | D50: Fruits | E50: 58917
...

Sheet Dashboard
D5: Total Revenue | G5: Total Purchase Volume | J5: Total Average income | M5: Average Regency
D8: 119538 | G8: 73591 | J8: 52247.251 | M8: 49.109375
